Workbook

Sheet Dashboard
A1: 📊 NUBANK VALUATION DASHBOARD | Nu Financeira S.A. | 30/06/2025
A2: DCF Model — Em R$ Milhares | Fonte: Demonstrações Contábeis H1 2025 (KPMG)
A4: SECTION 1 — VALUATION SUMMARY
A5: Valor Intrínseco por Ação (R$) | B5: ='DCF Valuation'!C33 -> 63.472161
A6: Enterprise Value — TEV (R$ mil) | B6: ='DCF Valuation'!C23 -> 2.7946548e+08
A7: Equity Value (R$ mil) | B7: ='DCF Valuation'!C28 -> 3.2665872e+08
A8: PV FCFF Período Explícito (R$ mil) | B8: ='DCF Valuation'!C10 -> 2.7946548e+08
A9: PV Terminal Value (R$ mil) | B9: ='DCF Valuation'!C20 -> 0
A10: WACC utilizado | B10: =Assumptions!B33 -> 0.063850447
A11: Terminal Growth Rate | B11: =Assumptions!G14 -> 0.03
A12: Data de Valuation | B12: =Assumptions!B7 -> 30/06/2025
A14: SECTION 2 — DEMONSTRATIVO FINANCEIRO HISTÓRICO vs. PROJETADO
A15: Indicador | B15: H1 2025 (Real) | C15: 2025E | D15: 2026E | E15: 2027E | F15: 2028E | G15: 2029E
A16: Receita Total (R$ mil) | B16: ='Historical Data'!D6 -> 30220364 | C16: ='Income Statement'!C9 -> 66484801 | D16: ='Income Statement'!D9 -> 73133281 | E16: ='Income Statement'!E9 -> 79715276 | F16: ='Income Statement'!F9 -> 86491075 | G16: ='Income Statement'!G9 -> 93410361
A17: Provisão ECL (R$ mil) | B17: ='Historical Data'!D14 -> -8459601 | C17: ='Income Statement'!C18 -> -10652987 | D17: ='Income Statement'!D18 -> -55928184 | E17: ='Income Statement'!E18 -> -74424434 | F17: ='Income Statement'!F18 -> -99016855 | G17: ='Income Statement'!G18 -> -1.3170698e+08
A18: Resultado Líquido (R$ mil) | B18: ='Historical Data'!D25 -> 5504578 | C18: ='Income Statement'!C29 -> 28101904 | D18: ='Income Statement'!D29 -> 2750389.4 | E18: ='Income Statement'!E29 -> -5577823.7 | F18: ='Income Statement'!F29 -> -17687600 | G18: ='Income Statement'!G29 -> -34880318
A19: FCFF (R$ mil) | B19: ='Historical Data'!D49 -> -50244 | C19: ='Cash Flow Projection'!C19 -> 55738231 | D19: ='Cash Flow Projection'!D19 -> 61917289 | E19: ='Cash Flow Projection'!E19 -> 67674150 | F19: ='Cash Flow Projection'!F19 -> 73676519 | G19: ='Cash Flow Projection'!G19 -> 79909726
A20: Operações de Crédito — Bruto | B20: ='Historical Data'!D31 -> 87678909 | C20: ='Income Statement'!C16 -> 1.1836653e+08 | D20: ='Income Statement'!D16 -> 1.5979481e+08 | E20: ='Income Statement'!E16 -> 2.15723e+08 | F20: ='Income Statement'!F16 -> 2.9122604e+08 | G20: ='Income Statement'!G16 -> 3.9315516e+08
A21: Net Margin | B21: ='Historical Data'!D61 -> 0.12114483 | C21: ='Income Statement'!C33 -> 0.42268163 | D21: ='Income Statement'!D33 -> 0.037607904 | E21: ='Income Statement'!E33 -> -0.069971829 | F21: ='Income Statement'!F33 -> -0.20450203 | G21: ='Income Statement'!G33 -> -0.37340952
A23: SECTION 3 — PREMISSAS-CHAVE
A24: Parâmetro | B24: 2025E | C24: 2026E | D24: 2027E | E24: 2028E | F24: 2029E | G24: Terminal
A25: Crescimento Receita | B25: =Assumptions!B14 -> 0.1 | C25: =Assumptions!C14 -> 0.1 | D25: =Assumptions!D14 -> 0.09 | E25: =Assumptions!E14 -> 0.085 | F25: =Assumptions!F14 -> 0.08 | G25: =Assumptions!G14 -> 0.03
A26: EBIT Margin | B26: =Assumptions!B15 -> 0.15 | C26: =Assumptions!C15 -> 0.155 | D26: =Assumptions!D15 -> 0.16 | E26: =Assumptions!E15 -> 0.165 | F26: =Assumptions!F15 -> 0.17 | G26: =Assumptions!G15 -> 0.17
A27: Tax Rate | B27: =Assumptions!B16 -> 0.363 | C27: =Assumptions!B16 -> 0.363 | D27: =Assumptions!B16 -> 0.363 | E27: =Assumptions!B16 -> 0.363 | F27: =Assumptions!B16 -> 0.363 | G27: =Assumptions!B16 -> 0.363
A28: WACC | B28: =Assumptions!B33 -> 0.063850447
A30: SECTION 4 — ANÁLISE DE SENSIBILIDADE (EXCERTO) — Valor por Ação (R$)
A31: Ver aba 'Sensitivity Analysis' para análise completa
A32: Rev. Growth \ WACC | B32: 5.50% | C32: 6.00% | D32: 6.38% | E32: 7.00% | F32: 7.50%
A33: 0.07 | B33: 166.7 | C33: 138.84 | D33: 123.18 | E33: 104.03 | F33: 92.43
A34: 0.09 | B34: 182.09 | C34: 151.54 | D34: 134.36 | E34: 113.36 | F34: 100.64
A35: 0.11 | B35: 198.63 | C35: 165.18 | D35: 146.38 | E35: 123.38 | F35: 109.46

Sheet Assumptions
A1: DCF MODEL — NU FINANCEIRA S.A. | Discounted Cash Flow Valuation (H1 2025)
A2: Demonstrações Contábeis — 30/06/2025 | Em R$ Milhares
A4: SECTION 1 — COMPANY & PERIOD INFORMATION
A5: Company Name | B5: Nu Financeira S.A.
A6: Ticker | B6: NUBANK (Nu Holdings Ltd.)
A7: Valuation Date | B7: 30/06/2025
A8: Analysis Period (Years) | B8: 5
A9: Currency | B9: BRL (Milhares)
A10: Last Fiscal Year Ended | B10: 30/06/2025
A12: SECTION 2 — ECONOMIC & MARKET ASSUMPTIONS
A13: Parâmetro | B13: 2025E | C13: 2026E | D13: 2027E | E13: 2028E | F13: 2029E | G13: Terminal
A14: Revenue Growth Rate | B14: 0.1 | C14: 0.1 | D14: 0.09 | E14: 0.085 | F14: 0.08 | G14: 0.03
A15: EBIT Margin | B15: 0.15 | C15: 0.155 | D15: 0.16 | E15: 0.165 | F15: 0.17 | G15: 0.17
A16: Tax Rate | B16: 0.363 | C16: 0.363 | D16: 0.363 | E16: 0.363 | F16: 0.363 | G16: 0.363
A17: CAPEX / Revenue | B17: 0.025 | C17: 0.025 | D17: 0.025 | E17: 0.025 | F17: 0.025 | G17: 0.025
A18: NWC Change / Revenue | B18: 0.005 | C18: 0.005 | D18: 0.005 | E18: 0.005 | F18: 0.005 | G18: 0.005
A20: SECTION 3 — WACC (WEIGHTED AVERAGE COST OF CAPITAL)
A21: Risk-Free Rate (Rf) | B21: 0.045
A22: Market Risk Premium (Rm-Rf) | B22: 0.06
A23: Beta (Financial Services) | B23: 0.95
A24: Cost of Equity (Ke) | B24: =B21+B23*B22 -> 0.102
A25: Weighted Avg Cost of Debt (pre-tax) | B25: 0.065
A26: Tax Rate | B26: =B16 -> 0.363
A27: After-Tax Cost of Debt (Kd) | B27: =B25*(1-B26) -> 0.041405
A28: Total Debt (R$ mil) | B28: 20453772
A29: Equity / Market Cap (R$ mil) | B29: 12034061
A30: Total Capital (R$ mil) | B30: =B28+B29 -> 32487833
A31: Debt Weight (D/V) | B31: =B28/B30 -> 0.62958253
A32: Equity Weight (E/V) | B32: =B29/B30 -> 0.37041747
A33: WACC | B33: =(B32*B24)+(B31*B27) -> 0.063850447
A35: SECTION 4 — CREDIT PORTFOLIO ASSUMPTIONS
A36: Total Gross Credit 30/06/2025 (R$ mil) | B36: 87678909
A37: Provision for Losses 30/06/2025 (R$ mil) | B37: 30721516
A38: Coverage Ratio | B38: 0.35
A39: Projected Credit Growth — Base Case | B39: 0.09
A40: Provision Rate 2025 | B40: 0.35
A41: Provision Rate 2026 | B41: 0.345
A42: Provision Rate 2027 | B42: 0.34
A43: Provision Rate 2028 | B43: 0.335
A44: Provision Rate 2029 | B44: 0.33
...

Sheet Historical Data
A1: NU FINANCEIRA S.A. — HISTORICAL FINANCIALS | H1 2025 (Semestre findo 30/06/2025)
A2: Em R$ Milhares | Fonte: Demonstrações Contábeis auditadas pela KPMG
A4: Item | B4: 2023E | C4: 2024E | D4: H1 2025
A5: DEMONSTRAÇÃO DO RESULTADO (DRE)
A6: Receitas de Intermediação Financeira | B6: [Est.] | C6: [Est.] | D6: 30220364
A7: Receita de Operações de Crédito | B7: [Est.] | C7: [Est.] | D7: 24467482
A8: Resultado de TVM | B8: [Est.] | C8: [Est.] | D8: 2969947
A9: Resultado de Depósitos no Banco Central | B9: [Est.] | C9: [Est.] | D9: 2782935
A10: Despesas de Intermediação Financeira | B10: [Est.] | C10: [Est.] | D10: -9474596
A11: Despesa de Juros e Similares | B11: [Est.] | C11: [Est.] | D11: -8940645
A12: Resultado com Derivativos | B12: [Est.] | C12: [Est.] | D12: -533951
A13: Resultado de Interm. Fin. (antes provisão) | B13: [Est.] | C13: [Est.] | D13: 20745768
A14: Provisão para Perdas Esperadas (ECL) | B14: [Est.] | C14: [Est.] | D14: -8459601
A15: Resultado de Intermediação Financeira | B15: [Est.] | C15: [Est.] | D15: 12286167
A16: Outras Receitas/Despesas Operacionais | B16: [Est.] | C16: [Est.] | D16: -3661041
A17: Despesas de Pessoal | B17: [Est.] | C17: [Est.] | D17: -854475
... A25: Resultado Líquido | B25: [Est.] | C25: [Est.] | D25: 5504578
A27: BALANÇO PATRIMONIAL (ITENS SELECIONADOS)
A28: Total do Ativo | B28: [Est.] | C28: [Est.] | D28: 191927308
A29: Caixa e Equivalentes de Caixa | B29: [Est.] | C29: [Est.] | D29: 26739469
A30: Ativos Financeiros — TVM | B30: [Est.] | C30: [Est.] | D30: 52607498
A31: Operações de Crédito — Bruto | B31: [Est.] | C31: [Est.] | D31: 87678909
A32: Provisão para Perdas (ECL) | B32: [Est.] | C32: [Est.] | D32: -30721516
A33: Operações de Crédito — Líquido | B33: [Est.] | C33: [Est.] | D33: 56957393
A34: Depósitos Compulsórios no BACEN | B34: [Est.] | C34: [Est.] | D34: 24817555
A35: Total do Passivo | B35: [Est.] | C35: [Est.] | D35: 179893247
A36: Depósitos (RDB + CDB) | B36: [Est.] | C36: [Est.] | D36: 144319559
A37: Empréstimos e Financiamentos | B37: [Est.] | C37: [Est.] | D37: 14581675
A38: Dívidas Subordinadas | B38: [Est.] | C38: [Est.] | D38: 5872097
A39: Obrigações Compromissadas | B39: [Est.] | C39: [Est.] | D39: 8787140
... A43: Lucros Acumulados | B43: [Est.] | C43: [Est.] | D43: 3586630
A45: DEMONSTRAÇÃO DO FLUXO DE CAIXA (DFC)
A46: Resultado Líquido | B46: [Est.] | C46: [Est.] | D46: 5504578
A47: Provisão para Perdas (ajuste não-caixa DFC) | B47: [Est.] | C47: [Est.] | D47: 10301739
A48: Depreciação/Amortização | B48: [Est.] | C48: [Est.] | D48: 16024
A49: Variação Valor Justo TVM | B49: [Est.] | C49: [Est.] | D49: -50244
A50: Fluxo Caixa Operacional | B50: [Est.] | C50: [Est.] | D50: 2957714
A51: Fluxo Caixa de Investimento | B51: [Est.] | C51: [Est.] | D51: -64198
A52: Fluxo Caixa de Financiamento | B52: [Est.] | C52: [Est.] | D52: 820321
A53: Variação Líquida de Caixa | B53: [Est.] | C53: [Est.] | D53: 3713837
...

Sheet Income Statement
A1: PROJECTED INCOME STATEMENT (2025E – 2029E) | Nu Financeira S.A.
A2: Em R$ Milhares | Projeção baseada em H1 2025 anualizado
A4: Item | B4: Nota | C4: 2025E | D4: 2026E | E4: 2027E | F4: 2028E | G4: 2029E
A5: RECEITAS DE INTERMEDIAÇÃO FINANCEIRA
A6: Receita de Operações de Crédito | C6: =C9*('Historical Data'!D7/'Historical Data'!D6) -> 53828460 | D6: =D9*('Historical Data'!D7/'Historical Data'!D6) -> 59211306 | E6: =E9*('Historical Data'!D7/'Historical Data'!D6) -> 64540324 | F6: =F9*('Historical Data'!D7/'Historical Data'!D6) -> 70026252 | G6: =G9*('Historical Data'!D7/'Historical Data'!D6) -> 75628352
A7: Resultado de TVM | C7: =C9*('Historical Data'!D8/'Historical Data'!D6) -> 6533883.4 | D7: =D9*('Historical Data'!D8/'Historical Data'!D6) -> 7187271.7 | E7: =E9*('Historical Data'!D8/'Historical Data'!D6) -> 7834126.2 | F7: =F9*('Historical Data'!D8/'Historical Data'!D6) -> 8500026.9 | G7: =G9*('Historical Data'!D8/'Historical Data'!D6) -> 9180029.1
A8: Resultado de Depósitos no BACEN e Outros | C8: =C9*('Historical Data'!D9/'Historical Data'!D6) -> 6122457 | D8: =D9*('Historical Data'!D9/'Historical Data'!D6) -> 6734702.7 | E8: =E9*('Historical Data'!D9/'Historical Data'!D6) -> 7340825.9 | F8: =F9*('Historical Data'!D9/'Historical Data'!D6) -> 7964796.1 | G8: =G9*('Historical Data'!D9/'Historical Data'!D6) -> 8601979.8
A9: Total Receitas Intermediação Financeira | C9: =('Historical Data'!D6*2)*(1+Assumptions!B14) -> 66484801 | D9: =C9*(1+Assumptions!C14) -> 73133281 | E9: =D9*(1+Assumptions!D14) -> 79715276 | F9: =E9*(1+Assumptions!E14) -> 86491075 | G9: =F9*(1+Assumptions!F14) -> 93410361
A10: DESPESAS DE INTERMEDIAÇÃO FINANCEIRA
A11: Despesa de Juros e Similares | C11: =C9*('Historical Data'!D11/'Historical Data'!D6) -> -19669419 | D11: =D9*('Historical Data'!D11/'Historical Data'!D6) -> -21636361 | E11: =E9*('Historical Data'!D11/'Historical Data'!D6) -> -23583633 | F11: =F9*('Historical Data'!D11/'Historical Data'!D6) -> -25588242 | G11: =G9*('Historical Data'!D11/'Historical Data'!D6) -> -27635302
A12: Resultado com Derivativos | C12: =C9*('Historical Data'!D12/'Historical Data'!D6) -> -1174692.2 | D12: =D9*('Historical Data'!D12/'Historical Data'!D6) -> -1292161.4 | E12: =E9*('Historical Data'!D12/'Historical Data'!D6) -> -1408455.9 | F12: =F9*('Historical Data'!D12/'Historical Data'!D6) -> -1528174.7 | G12: =G9*('Historical Data'!D12/'Historical Data'!D6) -> -1650428.7
A13: Total Despesas Intermediação Financeira | C13: =C11+C12 -> -20844111 | D13: =D11+D12 -> -22928522 | E13: =E11+E12 -> -24992089 | F13: =F11+F12 -> -27116417 | G13: =G11+G12 -> -29285730
A14: Resultado Interm. Fin. antes da Provisão | C14: =C9+C13 -> 45640690 | D14: =D9+D13 -> 50204759 | E14: =E9+E13 -> 54723187 | F14: =F9+F13 -> 59374658 | G14: =G9+G13 -> 64124630
A15: PROVISÃO PARA PERDAS ESPERADAS (ECL)
A16: Operações de Crédito — Bruto (projetado) | C16: ='Historical Data'!D31*(1+Assumptions!B38) -> 1.1836653e+08 | D16: =C16*(1+Assumptions!B38) -> 1.5979481e+08 | E16: =D16*(1+Assumptions!B38) -> 2.15723e+08 | F16: =E16*(1+Assumptions!B38) -> 2.9122604e+08 | G16: =F16*(1+Assumptions!B38) -> 3.9315516e+08
A17: Taxa de Provisão (% crédito bruto) | C17: =Assumptions!B39 -> 0.09 | D17: =Assumptions!B40 -> 0.35 | E17: =Assumptions!B41 -> 0.345 | F17: =Assumptions!B42 -> 0.34 | G17: =Assumptions!B43 -> 0.335
A18: Provisão para Perdas Esperadas (ECL) | C18: =-C16*Assumptions!B39 -> -10652987 | D18: =-D16*Assumptions!B40 -> -55928184 | E18: =-E16*Assumptions!B41 -> -74424434 | F18: =-F16*Assumptions!B42 -> -99016855 | G18: =-G16*Assumptions!B43 -> -1.3170698e+08
A19: Resultado de Interm. Financeira (após provisão) | C19: =C14+C18 -> 34987702 | D19: =D14+D18 -> -5723425.5 | E19: =E14+E18 -> -19701247 | F19: =F14+F18 -> -39642197 | G19: =G14+G18 -> -67582348
A20: OUTRAS RECEITAS/DESPESAS OPERACIONAIS
A21: Despesas de Pessoal | C21: ='Historical Data'!D17*(1+Assumptions!B14)*2 -> -1879845 | D21: =C21*(1+Assumptions!C14) -> -2067829.5 | E21: =D21*(1+Assumptions!D14) -> -2253934.2 | F21: =E21*(1+Assumptions!E14) -> -2445518.6 | G21: =F21*(1+Assumptions!F14) -> -2641160
A22: Despesas Tributárias | C22: ='Historical Data'!D18*(1+Assumptions!B14)*2 -> -2352552.4 | D22: =C22*(1+Assumptions!C14) -> -2587807.6 | E22: =D22*(1+Assumptions!D14) -> -2820710.3 | F22: =E22*(1+Assumptions!E14) -> -3060470.7 | G22: =F22*(1+Assumptions!F14) -> -3305308.4
A23: Despesas Gerais e Administrativas | C23: ='Historical Data'!D19*(1+Assumptions!B14)*2 -> -3333374 | D23: =C23*(1+Assumptions!C14) -> -3666711.4 | E23: =D23*(1+Assumptions!D14) -> -3996715.4 | F23: =E23*(1+Assumptions!E14) -> -4336436.2 | G23: =F23*(1+Assumptions!F14) -> -4683351.1
A24: Outras Receitas/Despesas Operacionais (líq.) | C24: =('Historical Data'!D21+'Historical Data'!D22+'Historical Data'!D23)*2 -> 16694088 | D24: =C24*(1+Assumptions!C14) -> 18363497 | E24: =D24*(1+Assumptions!D14) -> 20016212 | F24: =E24*(1+Assumptions!E14) -> 21717589 | G24: =F24*(1+Assumptions!F14) -> 23454997
A25: Total Outras Receitas/Despesas Operacionais | C25: =SUM(C21:C24) -> 9128316.6 | D25: =SUM(D21:D24) -> 10041148 | E25: =SUM(E21:E24) -> 10944852 | F25: =SUM(F21:F24) -> 11875164 | G25: =SUM(G21:G24) -> 12825177
A26: RESULTADO & TRIBUTOS
A27: Resultado antes dos Tributos (EBT) | C27: =C19+C25 -> 44116019 | D27: =D19+D25 -> 4317722.7 | E27: =E19+E25 -> -8756395.1 | F27: =F19+F25 -> -27767033 | G27: =G19+G25 -> -54757171
A28: Imposto de Renda e CSLL | C28: =-C27*Assumptions!B16 -> -16014115 | D28: =-D27*Assumptions!B16 -> -1567333.4 | E28: =-E27*Assumptions!B16 -> 3178571.4 | F28: =-F27*Assumptions!B16 -> 10079433 | G28: =-G27*Assumptions!B16 -> 19876853
A29: Resultado Líquido | C29: =C27+C28 -> 28101904 | D29: =D27+D28 -> 2750389.4 | E29: =E27+E28 -> -5577823.7 | F29: =F27+F28 -> -17687600 | G29: =G27+G28 -> -34880318
A31: INDICADORES
A32: EBIT Margin (EBT/Receita) | C32: =IFERROR(C27/C9,0) -> 0.66355044 | D32: =IFERROR(D27/D9,0) -> 0.059039095 | E32: =IFERROR(E27/E9,0) -> -0.10984589 | F32: =IFERROR(F27/F9,0) -> -0.32103929 | G32: =IFERROR(G27/G9,0) -> -0.58620019
A33: Net Margin (Liq./Receita) | C33: =IFERROR(C29/C9,0) -> 0.42268163 | D33: =IFERROR(D29/D9,0) -> 0.037607904 | E33: =IFERROR(E29/E9,0) -> -0.069971829 | F33: =IFERROR(F29/F9,0) -> -0.20450203 | G33: =IFERROR(G29/G9,0) -> -0.37340952
A34: Provision / Credit (taxa de provisão) | C34: =IFERROR(ABS(C18)/C16,0) -> 0.09 | D34: =IFERROR(ABS(D18)/D16,0) -> 0.35 | E34: =IFERROR(ABS(E18)/E16,0) -> 0.345 | F34: =IFERROR(ABS(F18)/F16,0) -> 0.34 | G34: =IFERROR(ABS(G18)/G16,0) -> 0.335

Sheet Cash Flow Projection
A1: PROJECTED FREE CASH FLOW TO FIRM (FCFF) | Nu Financeira S.A.
A2: Em R$ Milhares
A4: Item | B4: Nota | C4: 2025E | D4: 2026E | E4: 2027E | F4: 2028E | G4: 2029E
A5: EBIT & NOPAT
A6: EBIT (Resultado antes Tributos — IS) | C6: ='Income Statement'!C27 -> 44116019 | D6: ='Income Statement'!D27 -> 4317722.7 | E6: ='Income Statement'!E27 -> -8756395.1 | F6: ='Income Statement'!F27 -> -27767033 | G6: ='Income Statement'!G27 -> -54757171
A7: Impostos sobre EBIT | C7: =-C6*Assumptions!B16 -> -16014115 | D7: =-D6*Assumptions!B16 -> -1567333.4 | E7: =-E6*Assumptions!B16 -> 3178571.4 | F7: =-F6*Assumptions!B16 -> 10079433 | G7: =-G6*Assumptions!B16 -> 19876853
A8: NOPAT (Net Operating Profit After Tax) | C8: =C6+C7 -> 28101904 | D8: =D6+D7 -> 2750389.4 | E8: =E6+E7 -> -5577823.7 | F8: =F6+F7 -> -17687600 | G8: =G6+G7 -> -34880318
A9: AJUSTES NÃO-CAIXA
A10: Depreciação/Amortização | C10: ='Historical Data'!D47*2*(1+Assumptions!B14) -> 22663826 | D10: =C10*(1+Assumptions!C14) -> 24930208 | E10: =D10*(1+Assumptions!D14) -> 27173927 | F10: =E10*(1+Assumptions!E14) -> 29483711 | G10: =F10*(1+Assumptions!F14) -> 31842408
A11: Variação Provisão ECL (não-caixa) | C11: =ABS('Income Statement'!C18)*('Historical Data'!D46/ABS('Historical Data'!D14)) -> 6931792.7 | D11: =ABS('Income Statement'!D18)*('Historical Data'!D46/ABS('Historical Data'!D14)) -> 36391912 | E11: =ABS('Income Statement'!E18)*('Historical Data'!D46/ABS('Historical Data'!D14)) -> 48427237 | F11: =ABS('Income Statement'!F18)*('Historical Data'!D46/ABS('Historical Data'!D14)) -> 64429280 | G11: =ABS('Income Statement'!G18)*('Historical Data'!D46/ABS('Historical Data'!D14)) -> 85700417
A12: Outros Ajustes Não-Caixa | C12: ='Historical Data'!D48*2*(1+Assumptions!B14) -> 35252.8 | D12: =C12*(1+Assumptions!C14) -> 38778.08 | E12: =D12*(1+Assumptions!D14) -> 42268.107 | F12: =E12*(1+Assumptions!E14) -> 45860.896 | G12: =F12*(1+Assumptions!F14) -> 49529.768
A13: Total Ajustes Não-Caixa | C13: =SUM(C10:C12) -> 29630871 | D13: =SUM(D10:D12) -> 61360898 | E13: =SUM(E10:E12) -> 75643432 | F13: =SUM(F10:F12) -> 93958852 | G13: =SUM(G10:G12) -> 1.1759235e+08
A14: VARIAÇÃO NO CAPITAL DE GIRO (NWC)
A15: Variação no NWC (% Receita) | C15: =-'Income Statement'!C9*Assumptions!B18 -> -332424 | D15: =-'Income Statement'!D9*Assumptions!C18 -> -365666.4 | E15: =-'Income Statement'!E9*Assumptions!D18 -> -398576.38 | F15: =-'Income Statement'!F9*Assumptions!E18 -> -432455.37 | G15: =-'Income Statement'!G9*Assumptions!F18 -> -467051.8
A16: CAPEX (DESPESAS DE CAPITAL)
A17: CAPEX (% Receita) | C17: =-'Income Statement'!C9*Assumptions!B17 -> -1662120 | D17: =-'Income Statement'!D9*Assumptions!C17 -> -1828332 | E17: =-'Income Statement'!E9*Assumptions!D17 -> -1992881.9 | F17: =-'Income Statement'!F9*Assumptions!E17 -> -2162276.9 | G17: =-'Income Statement'!G9*Assumptions!F17 -> -2335259
A18: FREE CASH FLOW TO FIRM (FCFF)
A19: FREE CASH FLOW TO FIRM (FCFF) | C19: =C8+C13+C15+C17 -> 55738231 | D19: =D8+D13+D15+D17 -> 61917289 | E19: =E8+E13+E15+E17 -> 67674150 | F19: =F8+F13+F15+F17 -> 73676519 | G19: =G8+G13+G15+G17 -> 79909726
A21: INDICADORES FCF
A22: FCFF / Receita | C22: =IFERROR(C19/'Income Statement'!C9,0) -> 0.83836051 | D22: =IFERROR(D19/'Income Statement'!D9,0) -> 0.84663628 | E22: =IFERROR(E19/'Income Statement'!E9,0) -> 0.84894832 | F22: =IFERROR(F19/'Income Statement'!F9,0) -> 0.85183957 | G22: =IFERROR(G19/'Income Statement'!G9,0) -> 0.85546962
A23: NOPAT / Receita | C23: =IFERROR(C8/'Income Statement'!C9,0) -> 0.42268163 | D23: =IFERROR(D8/'Income Statement'!D9,0) -> 0.037607904 | E23: =IFERROR(E8/'Income Statement'!E9,0) -> -0.069971829 | F23: =IFERROR(F8/'Income Statement'!F9,0) -> -0.20450203 | G23: =IFERROR(G8/'Income Statement'!G9,0) -> -0.37340952

Sheet DCF Valuation
A1: DISCOUNTED CASH FLOW (DCF) VALUATION | Nu Financeira S.A.
A2: Em R$ Milhares
A4: Item | B4: Nota | C4: 2025E | D4: 2026E | E4: 2027E | F4: 2028E | G4: 2029E
A5: SECTION 1 — FREE CASH FLOW TO FIRM (FCFF) E VALOR PRESENTE
A6: Free Cash Flow to Firm (FCFF) | C6: ='Cash Flow Projection'!C19 -> 55738231 | D6: ='Cash Flow Projection'!D19 -> 61917289 | E6: ='Cash Flow Projection'!E19 -> 67674150 | F6: ='Cash Flow Projection'!F19 -> 73676519 | G6: ='Cash Flow Projection'!G19 -> 79909726
A7: Fator de Desconto (1+WACC)^t | C7: =(1+Assumptions!B33)^1 -> 1.0638504 | D7: =(1+Assumptions!B33)^2 -> 1.1317778 | E7: =(1+Assumptions!B33)^3 -> 1.2040423 | F7: =(1+Assumptions!B33)^4 -> 1.2809209 | G7: =(1+Assumptions!B33)^5 -> 1.3627083
A8: Valor Presente do FCFF | C8: =C6/C7 -> 52392920 | D8: =D6/D7 -> 54707992 | E8: =E6/E7 -> 56205792 | F8: =F6/F7 -> 57518398 | G8: =G6/G7 -> 58640375
A10: TOTAL PV FCFF — PERÍODO EXPLÍCITO (2025-2029) | C10: =SUM(C8:G8) -> 2.7946548e+08
A12: SECTION 2 — VALOR TERMINAL (GORDON GROWTH MODEL)
A13: FCFF no Ano Terminal (2029E) | C13: ='Cash Flow Projection'!G19 -> 79909726
A14: Taxa de Crescimento Terminal (g) | C14: =Assumptions!G14 -> 0.03
A15: WACC | C15: =Assumptions!B33 -> 0.063850447
A17: Terminal Value = FCFF_t × (1+g) / (WACC - g)
A18: Terminal Value (TV) | C18: =C13*(1+C14)/(C15-C14) -> 2.4314899e+09
A20: PV do Terminal Value = TV / (1+WACC)^5
A21: PV do Terminal Value | C21: =C18/((1+C15)^5) -> 1.7843069e+09
A22: SECTION 3 — ENTERPRISE VALUE & EQUITY VALUE
A23: Total Enterprise Value (TEV) | C23: =C10+C20 -> 2.7946548e+08
A24: Menos: Dívida Total (30/06/2025) | C24: =-Assumptions!B28 -> -20453772
A25: Menos: Interesses Minoritários | C25: 0
A26: Mais: Caixa e Equivalentes (30/06/2025) | C26: ='Historical Data'!D29 -> 26739469
A28: EQUITY VALUE (VALOR DO CAPITAL PRÓPRIO) | C28: =C23-C24+C25+C26 -> 3.2665872e+08
A30: SECTION 4 — VALOR INTRÍNSECO POR AÇÃO
A31: Número de Ações (em milhares) | C31: 5146488
A32: Equity Value (R$ mil) | C32: =C28 -> 3.2665872e+08
A33: VALOR INTRÍNSECO POR AÇÃO (R$) | C33: =IFERROR(C28/C31,0) -> 63.472161
A35: RESUMO DO VALUATION
A36: PV FCFF — Período Explícito (2025-2029) | C36: =C10 -> 2.7946548e+08
A37: PV do Valor Terminal | C37: =C20 -> 0
A38: Total Enterprise Value (TEV) | C38: =C23 -> 2.7946548e+08
A39: (-) Dívida Total | C39: =C24 -> -20453772
A40: (+) Caixa | C40: =C26 -> 26739469
A41: Equity Value | C41: =C28 -> 3.2665872e+08
A42: Valor por Ação (R$) | C42: =C33 -> 63.472161

Sheet Sensitivity Analysis
A1: SENSITIVITY ANALYSIS — VALOR INTRÍNSECO POR AÇÃO (R$) | Nu Financeira S.A.
A2: Variáveis: WACC (colunas) × Crescimento de Receita (linhas)
A4: WACC vs. CRESCIMENTO DE RECEITA — Valor por Ação (R$)
A5: Rev. Growth ↓ / WACC → | C5: 0.05 | D5: 0.055 | E5: 0.06 | F5: 0.065 | G5: 0.07 | H5: 0.075 | I5: 0.08
A6: 0.06 | C6: 199.29 | D6: 159.41 | E6: 132.83 | F6: 113.84 | G6: 99.61 | H6: 88.54 | I6: 79.68
A7: 0.07 | C7: 208.49 | D7: 166.7 | E7: 138.84 | F7: 118.94 | G7: 104.03 | H7: 92.43 | I7: 83.15
A8: 0.08 | C8: 218.04 | D8: 174.25 | E8: 145.07 | F8: 124.23 | G8: 108.61 | H8: 96.46 | I8: 86.75
A9: 0.09 | C9: 227.94 | D9: 182.09 | E9: 151.54 | F9: 129.72 | G9: 113.36 | H9: 100.64 | I9: 90.47
A10: 0.1 | C10: 238.2 | D10: 190.21 | E10: 158.23 | F10: 135.4 | G10: 118.28 | H10: 104.97 | I10: 94.33
A11: 0.11 | C11: 248.83 | D11: 198.63 | E11: 165.18 | F11: 141.29 | G11: 123.38 | H11: 109.46 | I11: 98.32
A12: 0.12 | C12: 259.85 | D12: 207.35 | E12: 172.37 | F12: 147.38 | G12: 128.66 | H12: 114.1 | I12: 102.46
A14: 🟨 Base Case (WACC≈6.38%, Growth=9%) 🟩 Upside 🟧 Moderate 🟥 Downside
A16: WACC vs. CRESCIMENTO TERMINAL — Valor por Ação (R$)
A17: Term. Growth ↓ / WACC → | C17: 0.05 | D17: 0.055 | E17: 0.06 | F17: 0.065 | G17: 0.07 | H17: 0.075 | I17: 0.08
A18: 0.02 | C18: 157.15 | D18: 134.46 | E18: 117.46 | F18: 104.24 | G18: 93.67 | H18: 85.02 | I18: 77.82
A19: 0.025 | C19: 185.46 | D19: 154.31 | E19: 132.06 | F19: 115.38 | G19: 102.42 | H19: 92.05 | I19: 83.57
A20: 0.03 | C20: 227.94 | D20: 182.09 | E20: 151.54 | F20: 129.72 | G20: 113.36 | H20: 100.64 | I20: 90.47
A21: 0.035 | C21: 298.73 | D21: 223.76 | E21: 178.8 | F21: 148.83 | G21: 127.43 | H21: 111.38 | I21: 98.9
A22: 0.04 | C22: 440.3 | D22: 293.22 | E22: 219.69 | F22: 175.58 | G22: 146.18 | H22: 125.19 | I22: 109.44
